Workbook

Sheet td
A3: Cuenta de DIIO | B3: Clase
A4: Rup_Actual | B4: TERNERA | C4: TERNERO | D4: Total general
A5: 11.2.01.0038 | B5: 59 | C5: 61 | D5: 120
A6: 11.1.01.2442 | B6: 52 | C6: 1 | D6: 53
A7: 11.1.01.1241 | B7: 40 | C7: 39 | D7: 79
A8: 11.1.01.0941 | B8: 8 | C8: 3 | D8: 11
A9: 11.1.01.0893 | B9: 1 | C9: 7 | D9: 8
A10: 11.1.01.0791 | B10: 58 | C10: 60 | D10: 118
A11: Total general | B11: 218 | C11: 171 | D11: 389
A24: Cuenta de DIIO | B24: Clase
A25: Rup_Actual | B25: BUEY | C25: NOVILLO | D25: TERNERA | E25: TERNERO | F25: TORO | G25: VACA | H25: VAQUILLA | I25: no existe | J25: TORITO | K25: Total general
A26: 11.1.01.0791 | B26: 2 | D26: 58 | E26: 60 | F26: 5 | G26: 140 | K26: 265
A27: 11.1.01.0870 | G27: 3 | K27: 3
A28: 11.1.01.0893 | C28: 1 | D28: 1 | E28: 7 | F28: 55 | G28: 82 | H28: 3 | K28: 149 | L28: es lo queda en sipec
A29: 11.1.01.0941 | C29: 3 | D29: 8 | E29: 3 | G29: 15 | H29: 129 | K29: 158
A30: 11.1.01.1022 | C30: 4 | F30: 1 | G30: 16 | H30: 81 | J30: 1 | K30: 103
A31: 11.1.01.1240 | G31: 5 | K31: 5
A32: 11.1.01.1241 | B32: 21 | C32: 8 | D32: 40 | E32: 39 | F32: 155 | G32: 493 | H32: 28 | K32: 784
A33: 11.2.01.0038 | B33: 3 | D33: 59 | E33: 61 | F33: 14 | G33: 201 | H33: 1 | K33: 339
A34: 11.1.01.2442 | B34: 2 | C34: 3 | D34: 52 | E34: 1 | F34: 15 | G34: 121 | H34: 24 | K34: 218
A35: no existe | I35: 31 | K35: 31
A36: 11.1.01.2304 | G36: 30 | H36: 4 | K36: 34
A37: Total general | B37: 28 | C37: 19 | D37: 218 | E37: 171 | F37: 245 | G37: 1106 | H37: 270 | I37: 31 | J37: 1 | K37: 2089
A57: Cuenta de DIIO | C57: Exportable_CHINA
A58: Clase | B58: Edad | C58: NO | D58: no existe | E58: SI | F58: Total general
A59: BUEY | B59: 13 años 1 meses | C59: 1 | F59: 1
B60: 23 años 11 meses | E60: 1 | F60: 1
B61: 19 años 2 meses | E61: 1 | F61: 1
B62: 6 años 2 meses | C62: 3 | F62: 3
B63: 21 años 4 meses | E63: 1 | F63: 1
B64: 20 años 3 meses | E64: 5 | F64: 5
B65: 19 años 3 meses | E65: 2 | F65: 2
B66: 18 años 9 meses | E66: 1 | F66: 1
B67: 18 años 3 meses | E67: 2 | F67: 2
B68: 13 años 3 meses | C68: 1 | F68: 1
B69: 11 años 3 meses | C69: 2 | F69: 2
B70: 12 años 3 meses | C70: 3 | F70: 3
B71: 8 años 3 meses | C71: 3 | F71: 3
B72: 7 años 3 meses | C72: 1 | F72: 1
B73: 6 años 3 meses | C73: 2 | F73: 2
...

Sheet tros(as)
A1: DIIO | B1: chip toro | C1: cambio diio (antiguo) | D1: manejo 2020 | E1: manejo 2021 | F1: manejo 2022 | G1: manejo 2023 | H1: manejo 2024 | I1: manejo 2025 | J1: Sexo | K1: Clase | L1: Raza | M1: Edad | N1: Fecha_Nacimiento | O1: Estado | P1: Rup_Actual | Q1: RUP_ultimo_movimiento | R1: Rup_Origen | S1: Exportable_CHINA | T1: fecha ident sipec
A2: 24567592 | J2: =VLOOKUP(A2,sinap!$A$2:$R$9000,2,FALSE) -> M | K2: =VLOOKUP(A2,sinap!$A$2:$R$9000,3,FALSE) -> TERNERO | L2: =VLOOKUP(A2,sinap!$A$2:$R$9000,4,FALSE) -> ANGUS ROJO | M2: =VLOOKUP(A2,sinap!$A$2:$R$9000,5,FALSE) -> 0 años 11 meses | N2: =VLOOKUP(A2,sinap!$A$2:$R$9000,6,FALSE) -> 30-01-2025 | O2: =VLOOKUP(A2,sinap!$A$2:$R$9000,7,FALSE) -> Vivo | P2: =VLOOKUP(A2,sinap!$A$2:$R$9000,8,FALSE) -> 11.1.01.1241 | Q2: =VLOOKUP(A2,sinap!$A$2:$R$9000,12,FALSE) -> Sin Movimiento | R2: =VLOOKUP(A2,sinap!$A$2:$R$9000,16,FALSE) -> 11.1.01.1241 | S2: =VLOOKUP(A2,sinap!$A$2:$Y$9000,20,FALSE) -> SI | T2: 45774
A3: 24567593 | J3: =VLOOKUP(A3,sinap!$A$2:$R$9000,2,FALSE) -> H | K3: =VLOOKUP(A3,sinap!$A$2:$R$9000,3,FALSE) -> TERNERA | L3: =VLOOKUP(A3,sinap!$A$2:$R$9000,4,FALSE) -> ANGUS ROJO | M3: =VLOOKUP(A3,sinap!$A$2:$R$9000,5,FALSE) -> 0 años 9 meses | N3: =VLOOKUP(A3,sinap!$A$2:$R$9000,6,FALSE) -> 30-03-2025 | O3: =VLOOKUP(A3,sinap!$A$2:$R$9000,7,FALSE) -> Vivo | P3: =VLOOKUP(A3,sinap!$A$2:$R$9000,8,FALSE) -> 11.1.01.2442 | Q3: =VLOOKUP(A3,sinap!$A$2:$R$9000,12,FALSE) -> 11.1.01.0190 | R3: =VLOOKUP(A3,sinap!$A$2:$R$9000,16,FALSE) -> 11.1.01.1241 | S3: =VLOOKUP(A3,sinap!$A$2:$Y$9000,20,FALSE) -> SI | T3: 45774
A4: 24567595 | J4: =VLOOKUP(A4,sinap!$A$2:$R$9000,2,FALSE) -> H | K4: =VLOOKUP(A4,sinap!$A$2:$R$9000,3,FALSE) -> TERNERA | L4: =VLOOKUP(A4,sinap!$A$2:$R$9000,4,FALSE) -> ANGUS NEGRO | M4: =VLOOKUP(A4,sinap!$A$2:$R$9000,5,FALSE) -> 0 años 9 meses | N4: =VLOOKUP(A4,sinap!$A$2:$R$9000,6,FALSE) -> 11-04-2025 | O4: =VLOOKUP(A4,sinap!$A$2:$R$9000,7,FALSE) -> Vivo | P4: =VLOOKUP(A4,sinap!$A$2:$R$9000,8,FALSE) -> 11.1.01.2442 | Q4: =VLOOKUP(A4,sinap!$A$2:$R$9000,12,FALSE) -> 11.1.01.0190 | R4: =VLOOKUP(A4,sinap!$A$2:$R$9000,16,FALSE) -> 11.1.01.1241 | S4: =VLOOKUP(A4,sinap!$A$2:$Y$9000,20,FALSE) -> SI | T4: 45774
A5: 24567596 | J5: =VLOOKUP(A5,sinap!$A$2:$R$9000,2,FALSE) -> H | K5: =VLOOKUP(A5,sinap!$A$2:$R$9000,3,FALSE) -> TERNERA | L5: =VLOOKUP(A5,sinap!$A$2:$R$9000,4,FALSE) -> ANGUS NEGRO | M5: =VLOOKUP(A5,sinap!$A$2:$R$9000,5,FALSE) -> 0 años 9 meses | N5: =VLOOKUP(A5,sinap!$A$2:$R$9000,6,FALSE) -> 11-04-2025 | O5: =VLOOKUP(A5,sinap!$A$2:$R$9000,7,FALSE) -> Vivo | P5: =VLOOKUP(A5,sinap!$A$2:$R$9000,8,FALSE) -> 11.1.01.2442 | Q5: =VLOOKUP(A5,sinap!$A$2:$R$9000,12,FALSE) -> 11.1.01.0190 | R5: =VLOOKUP(A5,sinap!$A$2:$R$9000,16,FALSE) -> 11.1.01.1241 | S5: =VLOOKUP(A5,sinap!$A$2:$Y$9000,20,FALSE) -> SI | T5: 45774
A6: 24567597 | J6: =VLOOKUP(A6,sinap!$A$2:$R$9000,2,FALSE) -> M | K6: =VLOOKUP(A6,sinap!$A$2:$R$9000,3,FALSE) -> TERNERO | L6: =VLOOKUP(A6,sinap!$A$2:$R$9000,4,FALSE) -> HEREFORD | M6: =VLOOKUP(A6,sinap!$A$2:$R$9000,5,FALSE) -> 0 años 9 meses | N6: =VLOOKUP(A6,sinap!$A$2:$R$9000,6,FALSE) -> 31-03-2025 | O6: =VLOOKUP(A6,sinap!$A$2:$R$9000,7,FALSE) -> Vivo | P6: =VLOOKUP(A6,sinap!$A$2:$R$9000,8,FALSE) -> 11.1.01.0941 | Q6: =VLOOKUP(A6,sinap!$A$2:$R$9000,12,FALSE) -> 11.1.01.1241 | R6: =VLOOKUP(A6,sinap!$A$2:$R$9000,16,FALSE) -> 11.1.01.1241 | S6: =VLOOKUP(A6,sinap!$A$2:$Y$9000,20,FALSE) -> SI | T6: 45774
A7: 24567598 | J7: =VLOOKUP(A7,sinap!$A$2:$R$9000,2,FALSE) -> H | K7: =VLOOKUP(A7,sinap!$A$2:$R$9000,3,FALSE) -> TERNERA | L7: =VLOOKUP(A7,sinap!$A$2:$R$9000,4,FALSE) -> ANGUS ROJO | M7: =VLOOKUP(A7,sinap!$A$2:$R$9000,5,FALSE) -> 0 años 10 meses | N7: =VLOOKUP(A7,sinap!$A$2:$R$9000,6,FALSE) -> 11-03-2025 | O7: =VLOOKUP(A7,sinap!$A$2:$R$9000,7,FALSE) -> Vivo | P7: =VLOOKUP(A7,sinap!$A$2:$R$9000,8,FALSE) -> 11.1.01.1241 | Q7: =VLOOKUP(A7,sinap!$A$2:$R$9000,12,FALSE) -> Sin Movimiento | R7: =VLOOKUP(A7,sinap!$A$2:$R$9000,16,FALSE) -> 11.1.01.1241 | S7: =VLOOKUP(A7,sinap!$A$2:$Y$9000,20,FALSE) -> SI | T7: 45774
A8: 24567599 | J8: =VLOOKUP(A8,sinap!$A$2:$R$9000,2,FALSE) -> H | K8: =VLOOKUP(A8,sinap!$A$2:$R$9000,3,FALSE) -> TERNERA | L8: =VLOOKUP(A8,sinap!$A$2:$R$9000,4,FALSE) -> ANGUS ROJO | M8: =VLOOKUP(A8,sinap!$A$2:$R$9000,5,FALSE) -> 0 años 10 meses | N8: =VLOOKUP(A8,sinap!$A$2:$R$9000,6,FALSE) -> 11-03-2025 | O8: =VLOOKUP(A8,sinap!$A$2:$R$9000,7,FALSE) -> Vivo | P8: =VLOOKUP(A8,sinap!$A$2:$R$9000,8,FALSE) -> 11.1.01.1241 | Q8: =VLOOKUP(A8,sinap!$A$2:$R$9000,12,FALSE) -> Sin Movimiento | R8: =VLOOKUP(A8,sinap!$A$2:$R$9000,16,FALSE) -> 11.1.01.1241 | S8: =VLOOKUP(A8,sinap!$A$2:$Y$9000,20,FALSE) -> SI | T8: 45774
A9: 26234001 | J9: =VLOOKUP(A9,sinap!$A$2:$R$9000,2,FALSE) -> H | K9: =VLOOKUP(A9,sinap!$A$2:$R$9000,3,FALSE) -> TERNERA | L9: =VLOOKUP(A9,sinap!$A$2:$R$9000,4,FALSE) -> ANGUS NEGRO | M9: =VLOOKUP(A9,sinap!$A$2:$R$9000,5,FALSE) -> 0 años 3 meses | N9: =VLOOKUP(A9,sinap!$A$2:$R$9000,6,FALSE) -> 30-09-2025 | O9: =VLOOKUP(A9,sinap!$A$2:$R$9000,7,FALSE) -> Vivo | P9: =VLOOKUP(A9,sinap!$A$2:$R$9000,8,FALSE) -> 11.1.01.2442 | Q9: =VLOOKUP(A9,sinap!$A$2:$R$9000,12,FALSE) -> 11.1.01.0190 | R9: =VLOOKUP(A9,sinap!$A$2:$R$9000,16,FALSE) -> 11.1.01.1241 | S9: =VLOOKUP(A9,sinap!$A$2:$Y$9000,20,FALSE) -> SI | T9: 45965
A10: 26234002 | J10: =VLOOKUP(A10,sinap!$A$2:$R$9000,2,FALSE) -> H | K10: =VLOOKUP(A10,sinap!$A$2:$R$9000,3,FALSE) -> TERNERA | L10: =VLOOKUP(A10,sinap!$A$2:$R$9000,4,FALSE) -> ANGUS NEGRO | M10: =VLOOKUP(A10,sinap!$A$2:$R$9000,5,FALSE) -> 0 años 3 meses | N10: =VLOOKUP(A10,sinap!$A$2:$R$9000,6,FALSE) -> 05-10-2025 | O10: =VLOOKUP(A10,sinap!$A$2:$R$9000,7,FALSE) -> Vivo | P10: =VLOOKUP(A10,sinap!$A$2:$R$9000,8,FALSE) -> 11.1.01.2442 | Q10: =VLOOKUP(A10,sinap!$A$2:$R$9000,12,FALSE) -> 11.1.01.0190 | R10: =VLOOKUP(A10,sinap!$A$2:$R$9000,16,FALSE) -> 11.1.01.1241 | S10: =VLOOKUP(A10,sinap!$A$2:$Y$9000,20,FALSE) -> SI | T10: 45965
A11: 26234012 | J11: =VLOOKUP(A11,sinap!$A$2:$R$9000,2,FALSE) -> H | K11: =VLOOKUP(A11,sinap!$A$2:$R$9000,3,FALSE) -> TERNERA | L11: =VLOOKUP(A11,sinap!$A$2:$R$9000,4,FALSE) -> ANGUS NEGRO | M11: =VLOOKUP(A11,sinap!$A$2:$R$9000,5,FALSE) -> 0 años 3 meses | N11: =VLOOKUP(A11,sinap!$A$2:$R$9000,6,FALSE) -> 05-10-2025 | O11: =VLOOKUP(A11,sinap!$A$2:$R$9000,7,FALSE) -> Vivo | P11: =VLOOKUP(A11,sinap!$A$2:$R$9000,8,FALSE) -> 11.1.01.2442 | Q11: =VLOOKUP(A11,sinap!$A$2:$R$9000,12,FALSE) -> 11.1.01.0190 | R11: =VLOOKUP(A11,sinap!$A$2:$R$9000,16,FALSE) -> 11.1.01.1241 | S11: =VLOOKUP(A11,sinap!$A$2:$Y$9000,20,FALSE) -> SI | T11: 45965
A12: 26234013 | J12: =VLOOKUP(A12,sinap!$A$2:$R$9000,2,FALSE) -> H | K12: =VLOOKUP(A12,sinap!$A$2:$R$9000,3,FALSE) -> TERNERA | L12: =VLOOKUP(A12,sinap!$A$2:$R$9000,4,FALSE) -> ANGUS NEGRO | M12: =VLOOKUP(A12,sinap!$A$2:$R$9000,5,FALSE) -> 0 años 4 meses | N12: =VLOOKUP(A12,sinap!$A$2:$R$9000,6,FALSE) -> 30-08-2025 | O12: =VLOOKUP(A12,sinap!$A$2:$R$9000,7,FALSE) -> Vivo | P12: =VLOOKUP(A12,sinap!$A$2:$R$9000,8,FALSE) -> 11.1.01.2442 | Q12: =VLOOKUP(A12,sinap!$A$2:$R$9000,12,FALSE) -> 11.1.01.0190 | R12: =VLOOKUP(A12,sinap!$A$2:$R$9000,16,FALSE) -> 11.1.01.1241 | S12: =VLOOKUP(A12,sinap!$A$2:$Y$9000,20,FALSE) -> SI | T12: 45965
A13: 26234014 | J13: =VLOOKUP(A13,sinap!$A$2:$R$9000,2,FALSE) -> H | K13: =VLOOKUP(A13,sinap!$A$2:$R$9000,3,FALSE) -> TERNERA | L13: =VLOOKUP(A13,sinap!$A$2:$R$9000,4,FALSE) -> ANGUS NEGRO | M13: =VLOOKUP(A13,sinap!$A$2:$R$9000,5,FALSE) -> 0 años 3 meses | N13: =VLOOKUP(A13,sinap!$A$2:$R$9000,6,FALSE) -> 05-10-2025 | O13: =VLOOKUP(A13,sinap!$A$2:$R$9000,7,FALSE) -> Vivo | P13: =VLOOKUP(A13,sinap!$A$2:$R$9000,8,FALSE) -> 11.1.01.2442 | Q13: =VLOOKUP(A13,sinap!$A$2:$R$9000,12,FALSE) -> 11.1.01.0190 | R13: =VLOOKUP(A13,sinap!$A$2:$R$9000,16,FALSE) -> 11.1.01.1241 | S13: =VLOOKUP(A13,sinap!$A$2:$Y$9000,20,FALSE) -> SI | T13: 45965
... A390: 26234485 | J390: =VLOOKUP(A390,sinap!$A$2:$R$9000,2,FALSE) -> H | K390: =VLOOKUP(A390,sinap!$A$2:$R$9000,3,FALSE) -> TERNERA | L390: =VLOOKUP(A390,sinap!$A$2:$R$9000,4,FALSE) -> ANGUS NEGRO | M390: =VLOOKUP(A390,sinap!$A$2:$R$9000,5,FALSE) -> 0 años 0 meses | N390: =VLOOKUP(A390,sinap!$A$2:$R$9000,6,FALSE) -> 21-12-2025 | O390: =VLOOKUP(A390,sinap!$A$2:$R$9000,7,FALSE) -> Vivo | P390: =VLOOKUP(A390,sinap!$A$2:$R$9000,8,FALSE) -> 11.1.01.0791 | Q390: =VLOOKUP(A390,sinap!$A$2:$R$9000,12,FALSE) -> 11.1.01.0893 | R390: =VLOOKUP(A390,sinap!$A$2:$R$9000,16,FALSE) -> 11.1.01.0893 | S390: =VLOOKUP(A390,sinap!$A$2:$Y$9000,20,FALSE) -> SI | T390: 46012

Sheet inventario
A1: DIIO | B1: chip toro | C1: cambio diio (antiguo) | D1: manejo 2020 | E1: manejo 2021 | F1: manejo 2022 | G1: manejo 2023 | H1: manejo 2024 | I1: manejo 2025 | J1: Sexo | K1: Clase | L1: Raza | M1: Edad | N1: Fecha_Nacimiento | O1: Estado | P1: Rup_Actual | Q1: RUP_ultimo_movimiento | R1: Rup_Origen | S1: Exportable_CHINA | T1: fecha ident sipec
A2: 55956 | J2: =VLOOKUP(A2,sinap!$A$2:$R$9000,2,FALSE) -> M | K2: =VLOOKUP(A2,sinap!$A$2:$R$9000,3,FALSE) -> BUEY | L2: =VLOOKUP(A2,sinap!$A$2:$R$9000,4,FALSE) -> OVERO COLORADO (CLAVEL ALEMAN) | M2: =VLOOKUP(A2,sinap!$A$2:$R$9000,5,FALSE) -> 23 años 11 meses | N2: =VLOOKUP(A2,sinap!$A$2:$R$9000,6,FALSE) -> 08-02-2002 | O2: =VLOOKUP(A2,sinap!$A$2:$R$9000,7,FALSE) -> Vivo | P2: =VLOOKUP(A2,sinap!$A$2:$R$9000,8,FALSE) -> 11.1.01.1241 | Q2: =VLOOKUP(A2,sinap!$A$2:$R$9000,12,FALSE) -> 11.1.01.0789 | R2: =VLOOKUP(A2,sinap!$A$2:$R$9000,16,FALSE) -> 11.1.01.0790 | S2: =VLOOKUP(A2,sinap!$A$2:$Y$9000,20,FALSE) -> SI
A3: 83926 | J3: =VLOOKUP(A3,sinap!$A$2:$R$9000,2,FALSE) -> M | K3: =VLOOKUP(A3,sinap!$A$2:$R$9000,3,FALSE) -> BUEY | L3: =VLOOKUP(A3,sinap!$A$2:$R$9000,4,FALSE) -> ANGUS NEGRO | M3: =VLOOKUP(A3,sinap!$A$2:$R$9000,5,FALSE) -> 21 años 4 meses | N3: =VLOOKUP(A3,sinap!$A$2:$R$9000,6,FALSE) -> 15-09-2004 | O3: =VLOOKUP(A3,sinap!$A$2:$R$9000,7,FALSE) -> Vivo | P3: =VLOOKUP(A3,sinap!$A$2:$R$9000,8,FALSE) -> 11.1.01.1241 | Q3: =VLOOKUP(A3,sinap!$A$2:$R$9000,12,FALSE) -> 11.1.01.0291 | R3: =VLOOKUP(A3,sinap!$A$2:$R$9000,16,FALSE) -> 11.1.01.0290 | S3: =VLOOKUP(A3,sinap!$A$2:$Y$9000,20,FALSE) -> SI
A4: 84361 | J4: =VLOOKUP(A4,sinap!$A$2:$R$9000,2,FALSE) -> H | K4: =VLOOKUP(A4,sinap!$A$2:$R$9000,3,FALSE) -> VACA | L4: =VLOOKUP(A4,sinap!$A$2:$R$9000,4,FALSE) -> POLLED HEREFORD | M4: =VLOOKUP(A4,sinap!$A$2:$R$9000,5,FALSE) -> 22 años 3 meses | N4: =VLOOKUP(A4,sinap!$A$2:$R$9000,6,FALSE) -> 15-10-2003 | O4: =VLOOKUP(A4,sinap!$A$2:$R$9000,7,FALSE) -> Vivo | P4: =VLOOKUP(A4,sinap!$A$2:$R$9000,8,FALSE) -> 11.1.01.1241 | Q4: =VLOOKUP(A4,sinap!$A$2:$R$9000,12,FALSE) -> 11.1.01.0791 | R4: =VLOOKUP(A4,sinap!$A$2:$R$9000,16,FALSE) -> 11.1.01.1241 | S4: =VLOOKUP(A4,sinap!$A$2:$Y$9000,20,FALSE) -> SI
A5: 84362 | J5: =VLOOKUP(A5,sinap!$A$2:$R$9000,2,FALSE) -> H | K5: =VLOOKUP(A5,sinap!$A$2:$R$9000,3,FALSE) -> VACA | L5: =VLOOKUP(A5,sinap!$A$2:$R$9000,4,FALSE) -> POLLED HEREFORD | M5: =VLOOKUP(A5,sinap!$A$2:$R$9000,5,FALSE) -> 22 años 3 meses | N5: =VLOOKUP(A5,sinap!$A$2:$R$9000,6,FALSE) -> 15-10-2003 | O5: =VLOOKUP(A5,sinap!$A$2:$R$9000,7,FALSE) -> Vivo | P5: =VLOOKUP(A5,sinap!$A$2:$R$9000,8,FALSE) -> 11.1.01.1241 | Q5: =VLOOKUP(A5,sinap!$A$2:$R$9000,12,FALSE) -> Sin Movimiento | R5: =VLOOKUP(A5,sinap!$A$2:$R$9000,16,FALSE) -> 11.1.01.1241 | S5: =VLOOKUP(A5,sinap!$A$2:$Y$9000,20,FALSE) -> SI
A6: 84369 | J6: =VLOOKUP(A6,sinap!$A$2:$R$9000,2,FALSE) -> H | K6: =VLOOKUP(A6,sinap!$A$2:$R$9000,3,FALSE) -> VACA | L6: =VLOOKUP(A6,sinap!$A$2:$R$9000,4,FALSE) -> OVERO COLORADO (CLAVEL ALEMAN) | M6: =VLOOKUP(A6,sinap!$A$2:$R$9000,5,FALSE) -> 22 años 3 meses | N6: =VLOOKUP(A6,sinap!$A$2:$R$9000,6,FALSE) -> 15-10-2003 | O6: =VLOOKUP(A6,sinap!$A$2:$R$9000,7,FALSE) -> Vivo | P6: =VLOOKUP(A6,sinap!$A$2:$R$9000,8,FALSE) -> 11.1.01.1241 | Q6: =VLOOKUP(A6,sinap!$A$2:$R$9000,12,FALSE) -> Sin Movimiento | R6: =VLOOKUP(A6,sinap!$A$2:$R$9000,16,FALSE) -> 11.1.01.1241 | S6: =VLOOKUP(A6,sinap!$A$2:$Y$9000,20,FALSE) -> SI
A7: 84393 | J7: =VLOOKUP(A7,sinap!$A$2:$R$9000,2,FALSE) -> H | K7: =VLOOKUP(A7,sinap!$A$2:$R$9000,3,FALSE) -> VACA | L7: =VLOOKUP(A7,sinap!$A$2:$R$9000,4,FALSE) -> POLLED HEREFORD | M7: =VLOOKUP(A7,sinap!$A$2:$R$9000,5,FALSE) -> 22 años 3 meses | N7: =VLOOKUP(A7,sinap!$A$2:$R$9000,6,FALSE) -> 15-10-2003 | O7: =VLOOKUP(A7,sinap!$A$2:$R$9000,7,FALSE) -> Vivo | P7: =VLOOKUP(A7,sinap!$A$2:$R$9000,8,FALSE) -> 11.1.01.1241 | Q7: =VLOOKUP(A7,sinap!$A$2:$R$9000,12,FALSE) -> 11.1.01.1081 | R7: =VLOOKUP(A7,sinap!$A$2:$R$9000,16,FALSE) -> 11.1.01.1241 | S7: =VLOOKUP(A7,sinap!$A$2:$Y$9000,20,FALSE) -> SI
A8: 84403 | J8: =VLOOKUP(A8,sinap!$A$2:$R$9000,2,FALSE) -> H | K8: =VLOOKUP(A8,sinap!$A$2:$R$9000,3,FALSE) -> VACA | L8: =VLOOKUP(A8,sinap!$A$2:$R$9000,4,FALSE) -> POLLED HEREFORD | M8: =VLOOKUP(A8,sinap!$A$2:$R$9000,5,FALSE) -> 22 años 3 meses | N8: =VLOOKUP(A8,sinap!$A$2:$R$9000,6,FALSE) -> 15-10-2003 | O8: =VLOOKUP(A8,sinap!$A$2:$R$9000,7,FALSE) -> Vivo | P8: =VLOOKUP(A8,sinap!$A$2:$R$9000,8,FALSE) -> 11.1.01.1241 | Q8: =VLOOKUP(A8,sinap!$A$2:$R$9000,12,FALSE) -> Sin Movimiento | R8: =VLOOKUP(A8,sinap!$A$2:$R$9000,16,FALSE) -> 11.1.01.1241 | S8: =VLOOKUP(A8,sinap!$A$2:$Y$9000,20,FALSE) -> SI
A9: 84427 | D9: 44121 | J9: =VLOOKUP(A9,sinap!$A$2:$R$9000,2,FALSE) -> H | K9: =VLOOKUP(A9,sinap!$A$2:$R$9000,3,FALSE) -> VACA | L9: =VLOOKUP(A9,sinap!$A$2:$R$9000,4,FALSE) -> ANGUS ROJO | M9: =VLOOKUP(A9,sinap!$A$2:$R$9000,5,FALSE) -> 21 años 3 meses | N9: =VLOOKUP(A9,sinap!$A$2:$R$9000,6,FALSE) -> 15-10-2004 | O9: =VLOOKUP(A9,sinap!$A$2:$R$9000,7,FALSE) -> Vivo | P9: =VLOOKUP(A9,sinap!$A$2:$R$9000,8,FALSE) -> 11.1.01.1241 | Q9: =VLOOKUP(A9,sinap!$A$2:$R$9000,12,FALSE) -> 11.1.01.0790 | R9: =VLOOKUP(A9,sinap!$A$2:$R$9000,16,FALSE) -> 11.1.01.0789 | S9: =VLOOKUP(A9,sinap!$A$2:$Y$9000,20,FALSE) -> SI
A10: 84463 | J10: =VLOOKUP(A10,sinap!$A$2:$R$9000,2,FALSE) -> H | K10: =VLOOKUP(A10,sinap!$A$2:$R$9000,3,FALSE) -> VACA | L10: =VLOOKUP(A10,sinap!$A$2:$R$9000,4,FALSE) -> OVERO COLORADO (CLAVEL ALEMAN) | M10: =VLOOKUP(A10,sinap!$A$2:$R$9000,5,FALSE) -> 22 años 3 meses | N10: =VLOOKUP(A10,sinap!$A$2:$R$9000,6,FALSE) -> 15-10-2003 | O10: =VLOOKUP(A10,sinap!$A$2:$R$9000,7,FALSE) -> Vivo | P10: =VLOOKUP(A10,sinap!$A$2:$R$9000,8,FALSE) -> 11.1.01.1241 | Q10: =VLOOKUP(A10,sinap!$A$2:$R$9000,12,FALSE) -> Sin Movimiento | R10: =VLOOKUP(A10,sinap!$A$2:$R$9000,16,FALSE) -> 11.1.01.1241 | S10: =VLOOKUP(A10,sinap!$A$2:$Y$9000,20,FALSE) -> SI
A11: 84657 | J11: =VLOOKUP(A11,sinap!$A$2:$R$9000,2,FALSE) -> H | K11: =VLOOKUP(A11,sinap!$A$2:$R$9000,3,FALSE) -> VACA | L11: =VLOOKUP(A11,sinap!$A$2:$R$9000,4,FALSE) -> HEREFORD | M11: =VLOOKUP(A11,sinap!$A$2:$R$9000,5,FALSE) -> 23 años 3 meses | N11: =VLOOKUP(A11,sinap!$A$2:$R$9000,6,FALSE) -> 15-10-2002 | O11: =VLOOKUP(A11,sinap!$A$2:$R$9000,7,FALSE) -> Vivo | P11: =VLOOKUP(A11,sinap!$A$2:$R$9000,8,FALSE) -> 11.1.01.1241 | Q11: =VLOOKUP(A11,sinap!$A$2:$R$9000,12,FALSE) -> 11.1.01.0791 | R11: =VLOOKUP(A11,sinap!$A$2:$R$9000,16,FALSE) -> 11.1.01.0791 | S11: =VLOOKUP(A11,sinap!$A$2:$Y$9000,20,FALSE) -> SI
A12: 93136 | J12: =VLOOKUP(A12,sinap!$A$2:$R$9000,2,FALSE) -> M | K12: =VLOOKUP(A12,sinap!$A$2:$R$9000,3,FALSE) -> BUEY | L12: =VLOOKUP(A12,sinap!$A$2:$R$9000,4,FALSE) -> ANGUS NEGRO | M12: =VLOOKUP(A12,sinap!$A$2:$R$9000,5,FALSE) -> 20 años 3 meses | N12: =VLOOKUP(A12,sinap!$A$2:$R$9000,6,FALSE) -> 25-09-2005 | O12: =VLOOKUP(A12,sinap!$A$2:$R$9000,7,FALSE) -> Vivo | P12: =VLOOKUP(A12,sinap!$A$2:$R$9000,8,FALSE) -> 11.1.01.1241 | Q12: =VLOOKUP(A12,sinap!$A$2:$R$9000,12,FALSE) -> 11.1.01.0790 | R12: =VLOOKUP(A12,sinap!$A$2:$R$9000,16,FALSE) -> 11.1.01.0831 | S12: =VLOOKUP(A12,sinap!$A$2:$Y$9000,20,FALSE) -> SI
A13: 133342 | J13: =VLOOKUP(A13,sinap!$A$2:$R$9000,2,FALSE) -> M | K13: =VLOOKUP(A13,sinap!$A$2:$R$9000,3,FALSE) -> BUEY | L13: =VLOOKUP(A13,sinap!$A$2:$R$9000,4,FALSE) -> OVERO COLORADO (CLAVEL ALEMAN) | M13: =VLOOKUP(A13,sinap!$A$2:$R$9000,5,FALSE) -> 20 años 3 meses | N13: =VLOOKUP(A13,sinap!$A$2:$R$9000,6,FALSE) -> 15-10-2005 | O13: =VLOOKUP(A13,sinap!$A$2:$R$9000,7,FALSE) -> Vivo | P13: =VLOOKUP(A13,sinap!$A$2:$R$9000,8,FALSE) -> 11.1.01.1241 | Q13: =VLOOKUP(A13,sinap!$A$2:$R$9000,12,FALSE) -> 11.1.01.0893 | R13: =VLOOKUP(A13,sinap!$A$2:$R$9000,16,FALSE) -> 11.1.01.0932 | S13: =VLOOKUP(A13,sinap!$A$2:$Y$9000,20,FALSE) -> SI
A14: 150564 | J14: =VLOOKUP(A14,sinap!$A$2:$R$9000,2,FALSE) -> H | K14: =VLOOKUP(A14,sinap!$A$2:$R$9000,3,FALSE) -> VACA | L14: =VLOOKUP(A14,sinap!$A$2:$R$9000,4,FALSE) -> OVERO COLORADO (CLAVEL ALEMAN) | M14: =VLOOKUP(A14,sinap!$A$2:$R$9000,5,FALSE) -> 22 años 4 meses | N14: =VLOOKUP(A14,sinap!$A$2:$R$9000,6,FALSE) -> 15-09-2003 | O14: =VLOOKUP(A14,sinap!$A$2:$R$9000,7,FALSE) -> Vivo | P14: =VLOOKUP(A14,sinap!$A$2:$R$9000,8,FALSE) -> 11.1.01.1241 | Q14: =VLOOKUP(A14,sinap!$A$2:$R$9000,12,FALSE) -> 11.1.01.1081 | R14: =VLOOKUP(A14,sinap!$A$2:$R$9000,16,FALSE) -> 11.2.02.0112 | S14: =VLOOKUP(A14,sinap!$A$2:$Y$9000,20,FALSE) -> SI
A15: 161892 | D15: 43983 | E15: 44491 | F15: 44883 | G15: 45253 | J15: =VLOOKUP(A15,sinap!$A$2:$R$9000,2,FALSE) -> H | K15: =VLOOKUP(A15,sinap!$A$2:$R$9000,3,FALSE) -> VACA | L15: =VLOOKUP(A15,sinap!$A$2:$R$9000,4,FALSE) -> POLLED HEREFORD | M15: =VLOOKUP(A15,sinap!$A$2:$R$9000,5,FALSE) -> 24 años 3 meses | N15: =VLOOKUP(A15,sinap!$A$2:$R$9000,6,FALSE) -> 15-10-2001 | O15: =VLOOKUP(A15,sinap!$A$2:$R$9000,7,FALSE) -> Vivo | P15: =VLOOKUP(A15,sinap!$A$2:$R$9000,8,FALSE) -> 11.1.01.1241 | Q15: =VLOOKUP(A15,sinap!$A$2:$R$9000,12,FALSE) -> Sin Movimiento | R15: =VLOOKUP(A15,sinap!$A$2:$R$9000,16,FALSE) -> 11.1.01.1241 | S15: =VLOOKUP(A15,sinap!$A$2:$Y$9000,20,FALSE) -> SI
A16: 176301 | E16: 44491 | F16: 44893 | G16: 45240 | J16: =VLOOKUP(A16,sinap!$A$2:$R$9000,2,FALSE) -> M | K16: =VLOOKUP(A16,sinap!$A$2:$R$9000,3,FALSE) -> BUEY | L16: =VLOOKUP(A16,sinap!$A$2:$R$9000,4,FALSE) -> ANGUS NEGRO | M16: =VLOOKUP(A16,sinap!$A$2:$R$9000,5,FALSE) -> 20 años 3 meses | N16: =VLOOKUP(A16,sinap!$A$2:$R$9000,6,FALSE) -> 15-10-2005 | O16: =VLOOKUP(A16,sinap!$A$2:$R$9000,7,FALSE) -> Vivo | P16: =VLOOKUP(A16,sinap!$A$2:$R$9000,8,FALSE) -> 11.1.01.1241 | Q16: =VLOOKUP(A16,sinap!$A$2:$R$9000,12,FALSE) -> 11.1.01.1081 | R16: =VLOOKUP(A16,sinap!$A$2:$R$9000,16,FALSE) -> 11.1.01.0290 | S16: =VLOOKUP(A16,sinap!$A$2:$Y$9000,20,FALSE) -> SI
A17: 176307 | J17: =VLOOKUP(A17,sinap!$A$2:$R$9000,2,FALSE) -> M | K17: =VLOOKUP(A17,sinap!$A$2:$R$9000,3,FALSE) -> BUEY | L17: =VLOOKUP(A17,sinap!$A$2:$R$9000,4,FALSE) -> ANGUS NEGRO | M17: =VLOOKUP(A17,sinap!$A$2:$R$9000,5,FALSE) -> 20 años 3 meses | N17: =VLOOKUP(A17,sinap!$A$2:$R$9000,6,FALSE) -> 15-10-2005 | O17: =VLOOKUP(A17,sinap!$A$2:$R$9000,7,FALSE) -> Vivo | P17: =VLOOKUP(A17,sinap!$A$2:$R$9000,8,FALSE) -> 11.1.01.1241 | Q17: =VLOOKUP(A17,sinap!$A$2:$R$9000,12,FALSE) -> 11.1.01.0290 | R17: =VLOOKUP(A17,sinap!$A$2:$R$9000,16,FALSE) -> 11.1.01.0290 | S17: =VLOOKUP(A17,sinap!$A$2:$Y$9000,20,FALSE) -> SI
A18: 180512 | E18: 44491 | G18: 45090 | J18: =VLOOKUP(A18,sinap!$A$2:$R$9000,2,FALSE) -> H | K18: =VLOOKUP(A18,sinap!$A$2:$R$9000,3,FALSE) -> VACA | L18: =VLOOKUP(A18,sinap!$A$2:$R$9000,4,FALSE) -> HEREFORD | M18: =VLOOKUP(A18,sinap!$A$2:$R$9000,5,FALSE) -> 20 años 3 meses | N18: =VLOOKUP(A18,sinap!$A$2:$R$9000,6,FALSE) -> 15-10-2005 | O18: =VLOOKUP(A18,sinap!$A$2:$R$9000,7,FALSE) -> Vivo | P18: =VLOOKUP(A18,sinap!$A$2:$R$9000,8,FALSE) -> 11.1.01.1241 | Q18: =VLOOKUP(A18,sinap!$A$2:$R$9000,12,FALSE) -> 11.1.01.0791 | R18: =VLOOKUP(A18,sinap!$A$2:$R$9000,16,FALSE) -> 11.1.01.0791 | S18: =VLOOKUP(A18,sinap!$A$2:$Y$9000,20,FALSE) -> SI
A19: 180524 | E19: 44491 | F19: 44908 | G19: 45265 | J19: =VLOOKUP(A19,sinap!$A$2:$R$9000,2,FALSE) -> H | K19: =VLOOKUP(A19,sinap!$A$2:$R$9000,3,FALSE) -> VACA | L19: =VLOOKUP(A19,sinap!$A$2:$R$9000,4,FALSE) -> HEREFORD | M19: =VLOOKUP(A19,sinap!$A$2:$R$9000,5,FALSE) -> 20 años 3 meses | N19: =VLOOKUP(A19,sinap!$A$2:$R$9000,6,FALSE) -> 15-10-2005 | O19: =VLOOKUP(A19,sinap!$A$2:$R$9000,7,FALSE) -> Vivo | P19: =VLOOKUP(A19,sinap!$A$2:$R$9000,8,FALSE) -> 11.1.01.1241 | Q19: =VLOOKUP(A19,sinap!$A$2:$R$9000,12,FALSE) -> 11.1.01.1240 | R19: =VLOOKUP(A19,sinap!$A$2:$R$9000,16,FALSE) -> 11.1.01.0791 | S19: =VLOOKUP(A19,sinap!$A$2:$Y$9000,20,FALSE) -> SI
A20: 180528 | J20: =VLOOKUP(A20,sinap!$A$2:$R$9000,2,FALSE) -> H | K20: =VLOOKUP(A20,sinap!$A$2:$R$9000,3,FALSE) -> VACA | L20: =VLOOKUP(A20,sinap!$A$2:$R$9000,4,FALSE) -> HEREFORD | M20: =VLOOKUP(A20,sinap!$A$2:$R$9000,5,FALSE) -> 20 años 3 meses | N20: =VLOOKUP(A20,sinap!$A$2:$R$9000,6,FALSE) -> 15-10-2005 | O20: =VLOOKUP(A20,sinap!$A$2:$R$9000,7,FALSE) -> Vivo | P20: =VLOOKUP(A20,sinap!$A$2:$R$9000,8,FALSE) -> 11.1.01.1241 | Q20: =VLOOKUP(A20,sinap!$A$2:$R$9000,12,FALSE) -> 11.1.01.0789 | R20: =VLOOKUP(A20,sinap!$A$2:$R$9000,16,FALSE) -> 11.1.01.0791 | S20: =VLOOKUP(A20,sinap!$A$2:$Y$9000,20,FALSE) -> SI
A21: 180529 | J21: =VLOOKUP(A21,sinap!$A$2:$R$9000,2,FALSE) -> H | K21: =VLOOKUP(A21,sinap!$A$2:$R$9000,3,FALSE) -> VACA | L21: =VLOOKUP(A21,sinap!$A$2:$R$9000,4,FALSE) -> HEREFORD | M21: =VLOOKUP(A21,sinap!$A$2:$R$9000,5,FALSE) -> 20 años 1 meses | N21: =VLOOKUP(A21,sinap!$A$2:$R$9000,6,FALSE) -> 15-12-2005 | O21: =VLOOKUP(A21,sinap!$A$2:$R$9000,7,FALSE) -> Vivo | P21: =VLOOKUP(A21,sinap!$A$2:$R$9000,8,FALSE) -> 11.1.01.1241 | Q21: =VLOOKUP(A21,sinap!$A$2:$R$9000,12,FALSE) -> 11.1.01.1240 | R21: =VLOOKUP(A21,sinap!$A$2:$R$9000,16,FALSE) -> 11.1.01.1240 | S21: =VLOOKUP(A21,sinap!$A$2:$Y$9000,20,FALSE) -> SI
A22: 180560 | J22: =VLOOKUP(A22,sinap!$A$2:$R$9000,2,FALSE) -> H | K22: =VLOOKUP(A22,sinap!$A$2:$R$9000,3,FALSE) -> VACA | L22: =VLOOKUP(A22,sinap!$A$2:$R$9000,4,FALSE) -> OVERO COLORADO (CLAVEL ALEMAN) | M22: =VLOOKUP(A22,sinap!$A$2:$R$9000,5,FALSE) -> 20 años 3 meses | N22: =VLOOKUP(A22,sinap!$A$2:$R$9000,6,FALSE) -> 15-10-2005 | O22: =VLOOKUP(A22,sinap!$A$2:$R$9000,7,FALSE) -> Vivo | P22: =VLOOKUP(A22,sinap!$A$2:$R$9000,8,FALSE) -> 11.1.01.1241 | Q22: =VLOOKUP(A22,sinap!$A$2:$R$9000,12,FALSE) -> 11.2.01.0038 | R22: =VLOOKUP(A22,sinap!$A$2:$R$9000,16,FALSE) -> 11.1.01.1241 | S22: =VLOOKUP(A22,sinap!$A$2:$Y$9000,20,FALSE) -> SI
A23: 180572 | J23: =VLOOKUP(A23,sinap!$A$2:$R$9000,2,FALSE) -> H | K23: =VLOOKUP(A23,sinap!$A$2:$R$9000,3,FALSE) -> VACA | L23: =VLOOKUP(A23,sinap!$A$2:$R$9000,4,FALSE) -> OVERO COLORADO (CLAVEL ALEMAN) | M23: =VLOOKUP(A23,sinap!$A$2:$R$9000,5,FALSE) -> 20 años 3 meses | N23: =VLOOKUP(A23,sinap!$A$2:$R$9000,6,FALSE) -> 15-10-2005 | O23: =VLOOKUP(A23,sinap!$A$2:$R$9000,7,FALSE) -> Vivo | P23: =VLOOKUP(A23,sinap!$A$2:$R$9000,8,FALSE) -> 11.1.01.1241 | Q23: =VLOOKUP(A23,sinap!$A$2:$R$9000,12,FALSE) -> 11.2.01.0053 | R23: =VLOOKUP(A23,sinap!$A$2:$R$9000,16,FALSE) -> 11.1.01.1241 | S23: =VLOOKUP(A23,sinap!$A$2:$Y$9000,20,FALSE) -> SI
A24: 180592 | J24: =VLOOKUP(A24,sinap!$A$2:$R$9000,2,FALSE) -> H | K24: =VLOOKUP(A24,sinap!$A$2:$R$9000,3,FALSE) -> VACA | L24: =VLOOKUP(A24,sinap!$A$2:$R$9000,4,FALSE) -> OVERO COLORADO (CLAVEL ALEMAN) | M24: =VLOOKUP(A24,sinap!$A$2:$R$9000,5,FALSE) -> 20 años 3 meses | N24: =VLOOKUP(A24,sinap!$A$2:$R$9000,6,FALSE) -> 15-10-2005 | O24: =VLOOKUP(A24,sinap!$A$2:$R$9000,7,FALSE) -> Vivo | P24: =VLOOKUP(A24,sinap!$A$2:$R$9000,8,FALSE) -> 11.1.01.1241 | Q24: =VLOOKUP(A24,sinap!$A$2:$R$9000,12,FALSE) -> 11.1.01.1240 | R24: =VLOOKUP(A24,sinap!$A$2:$R$9000,16,FALSE) -> 11.1.01.1241 | S24: =VLOOKUP(A24,sinap!$A$2:$Y$9000,20,FALSE) -> SI
A25: 180666 | J25: =VLOOKUP(A25,sinap!$A$2:$R$9000,2,FALSE) -> H | K25: =VLOOKUP(A25,sinap!$A$2:$R$9000,3,FALSE) -> VACA | L25: =VLOOKUP(A25,sinap!$A$2:$R$9000,4,FALSE) -> OVERO COLORADO (CLAVEL ALEMAN) | M25: =VLOOKUP(A25,sinap!$A$2:$R$9000,5,FALSE) -> 20 años 1 meses | N25: =VLOOKUP(A25,sinap!$A$2:$R$9000,6,FALSE) -> 15-12-2005 | O25: =VLOOKUP(A25,sinap!$A$2:$R$9000,7,FALSE) -> Vivo | P25: =VLOOKUP(A25,sinap!$A$2:$R$9000,8,FALSE) -> 11.1.01.1241 | Q25: =VLOOKUP(A25,sinap!$A$2:$R$9000,12,FALSE) -> 11.1.01.0791 | R25: =VLOOKUP(A25,sinap!$A$2:$R$9000,16,FALSE) -> 11.1.01.1241 | S25: =VLOOKUP(A25,sinap!$A$2:$Y$9000,20,FALSE) -> SI
A26: 180700 | J26: =VLOOKUP(A26,sinap!$A$2:$R$9000,2,FALSE) -> H | K26: =VLOOKUP(A26,sinap!$A$2:$R$9000,3,FALSE) -> VACA | L26: =VLOOKUP(A26,sinap!$A$2:$R$9000,4,FALSE) -> HEREFORD | M26: =VLOOKUP(A26,sinap!$A$2:$R$9000,5,FALSE) -> 20 años 4 meses | N26: =VLOOKUP(A26,sinap!$A$2:$R$9000,6,FALSE) -> 15-09-2005 | O26: =VLOOKUP(A26,sinap!$A$2:$R$9000,7,FALSE) -> Vivo | P26: =VLOOKUP(A26,sinap!$A$2:$R$9000,8,FALSE) -> 11.1.01.1241 | Q26: =VLOOKUP(A26,sinap!$A$2:$R$9000,12,FALSE) -> 11.2.01.2071 | R26: =VLOOKUP(A26,sinap!$A$2:$R$9000,16,FALSE) -> 11.1.01.0790 | S26: =VLOOKUP(A26,sinap!$A$2:$Y$9000,20,FALSE) -> SI
A27: 180705 | J27: =VLOOKUP(A27,sinap!$A$2:$R$9000,2,FALSE) -> H | K27: =VLOOKUP(A27,sinap!$A$2:$R$9000,3,FALSE) -> VACA | L27: =VLOOKUP(A27,sinap!$A$2:$R$9000,4,FALSE) -> OVERO COLORADO (CLAVEL ALEMAN) | M27: =VLOOKUP(A27,sinap!$A$2:$R$9000,5,FALSE) -> 20 años 4 meses | N27: =VLOOKUP(A27,sinap!$A$2:$R$9000,6,FALSE) -> 15-09-2005 | O27: =VLOOKUP(A27,sinap!$A$2:$R$9000,7,FALSE) -> Vivo | P27: =VLOOKUP(A27,sinap!$A$2:$R$9000,8,FALSE) -> 11.1.01.1241 | Q27: =VLOOKUP(A27,sinap!$A$2:$R$9000,12,FALSE) -> 11.1.01.0791 | R27: =VLOOKUP(A27,sinap!$A$2:$R$9000,16,FALSE) -> 11.1.01.0790 | S27: =VLOOKUP(A27,sinap!$A$2:$Y$9000,20,FALSE) -> SI
A28: 180717 | J28: =VLOOKUP(A28,sinap!$A$2:$R$9000,2,FALSE) -> H | K28: =VLOOKUP(A28,sinap!$A$2:$R$9000,3,FALSE) -> VACA | L28: =VLOOKUP(A28,sinap!$A$2:$R$9000,4,FALSE) -> HEREFORD | M28: =VLOOKUP(A28,sinap!$A$2:$R$9000,5,FALSE) -> 20 años 3 meses | N28: =VLOOKUP(A28,sinap!$A$2:$R$9000,6,FALSE) -> 15-10-2005 | O28: =VLOOKUP(A28,sinap!$A$2:$R$9000,7,FALSE) -> Vivo | P28: =VLOOKUP(A28,sinap!$A$2:$R$9000,8,FALSE) -> 11.1.01.1241 | Q28: =VLOOKUP(A28,sinap!$A$2:$R$9000,12,FALSE) -> 11.1.01.0791 | R28: =VLOOKUP(A28,sinap!$A$2:$R$9000,16,FALSE) -> 11.1.01.0790 | S28: =VLOOKUP(A28,sinap!$A$2:$Y$9000,20,FALSE) -> SI
A29: 180721 | D29: 44133 | E29: 44518 | F29: 44893 | G29: 45254 | J29: =VLOOKUP(A29,sinap!$A$2:$R$9000,2,FALSE) -> H | K29: =VLOOKUP(A29,sinap!$A$2:$R$9000,3,FALSE) -> VACA | L29: =VLOOKUP(A29,sinap!$A$2:$R$9000,4,FALSE) -> HEREFORD | M29: =VLOOKUP(A29,sinap!$A$2:$R$9000,5,FALSE) -> 20 años 3 meses | N29: =VLOOKUP(A29,sinap!$A$2:$R$9000,6,FALSE) -> 15-10-2005 | O29: =VLOOKUP(A29,sinap!$A$2:$R$9000,7,FALSE) -> Vivo | P29: =VLOOKUP(A29,sinap!$A$2:$R$9000,8,FALSE) -> 11.1.01.1241 | Q29: =VLOOKUP(A29,sinap!$A$2:$R$9000,12,FALSE) -> 11.1.01.0791 | R29: =VLOOKUP(A29,sinap!$A$2:$R$9000,16,FALSE) -> 11.1.01.0790 | S29: =VLOOKUP(A29,sinap!$A$2:$Y$9000,20,FALSE) -> SI
A30: 1316934 | D30: 43983 | E30: 44491 | F30: 44912 | G30: 45253 | J30: =VLOOKUP(A30,sinap!$A$2:$R$9000,2,FALSE) -> M | K30: =VLOOKUP(A30,sinap!$A$2:$R$9000,3,FALSE) -> BUEY | L30: =VLOOKUP(A30,sinap!$A$2:$R$9000,4,FALSE) -> ANGUS NEGRO | M30: =VLOOKUP(A30,sinap!$A$2:$R$9000,5,FALSE) -> 19 años 3 meses | N30: =VLOOKUP(A30,sinap!$A$2:$R$9000,6,FALSE) -> 15-10-2006 | O30: =VLOOKUP(A30,sinap!$A$2:$R$9000,7,FALSE) -> Vivo | P30: =VLOOKUP(A30,sinap!$A$2:$R$9000,8,FALSE) -> 11.1.01.1241 | Q30: =VLOOKUP(A30,sinap!$A$2:$R$9000,12,FALSE) -> 11.1.01.0290 | R30: =VLOOKUP(A30,sinap!$A$2:$R$9000,16,FALSE) -> 11.1.01.0290 | S30: =VLOOKUP(A30,sinap!$A$2:$Y$9000,20,FALSE) -> SI
A31: 1316953 | J31: =VLOOKUP(A31,sinap!$A$2:$R$9000,2,FALSE) -> M | K31: =VLOOKUP(A31,sinap!$A$2:$R$9000,3,FALSE) -> BUEY | L31: =VLOOKUP(A31,sinap!$A$2:$R$9000,4,FALSE) -> ANGUS ROJO | M31: =VLOOKUP(A31,sinap!$A$2:$R$9000,5,FALSE) -> 19 años 2 meses | N31: =VLOOKUP(A31,sinap!$A$2:$R$9000,6,FALSE) -> 30-10-2006 | O31: =VLOOKUP(A31,sinap!$A$2:$R$9000,7,FALSE) -> Vivo | P31: =VLOOKUP(A31,sinap!$A$2:$R$9000,8,FALSE) -> 11.1.01.1241 | Q31: =VLOOKUP(A31,sinap!$A$2:$R$9000,12,FALSE) -> 11.1.01.0790 | R31: =VLOOKUP(A31,sinap!$A$2:$R$9000,16,FALSE) -> 11.1.01.0790 | S31: =VLOOKUP(A31,sinap!$A$2:$Y$9000,20,FALSE) -> SI
A32: 1316957 | D32: 43983 | E32: 44491 | F32: 44908 | G32: 45253 | J32: =VLOOKUP(A32,sinap!$A$2:$R$9000,2,FALSE) -> H | K32: =VLOOKUP(A32,sinap!$A$2:$R$9000,3,FALSE) -> VACA | L32: =VLOOKUP(A32,sinap!$A$2:$R$9000,4,FALSE) -> OVERO COLORADO (CLAVEL ALEMAN) | M32: =VLOOKUP(A32,sinap!$A$2:$R$9000,5,FALSE) -> 19 años 2 meses | N32: =VLOOKUP(A32,sinap!$A$2:$R$9000,6,FALSE) -> 30-10-2006 | O32: =VLOOKUP(A32,sinap!$A$2:$R$9000,7,FALSE) -> Vivo | P32: =VLOOKUP(A32,sinap!$A$2:$R$9000,8,FALSE) -> 11.1.01.1241 | Q32: =VLOOKUP(A32,sinap!$A$2:$R$9000,12,FALSE) -> 11.2.01.0053 | R32: =VLOOKUP(A32,sinap!$A$2:$R$9000,16,FALSE) -> 11.1.01.0790 | S32: =VLOOKUP(A32,sinap!$A$2:$Y$9000,20,FALSE) -> SI
A33: 1316967 | D33: 44133 | E33: 44518 | F33: 44883 | J33: =VLOOKUP(A33,sinap!$A$2:$R$9000,2,FALSE) -> H | K33: =VLOOKUP(A33,sinap!$A$2:$R$9000,3,FALSE) -> VACA | L33: =VLOOKUP(A33,sinap!$A$2:$R$9000,4,FALSE) -> HEREFORD | M33: =VLOOKUP(A33,sinap!$A$2:$R$9000,5,FALSE) -> 19 años 1 meses | N33: =VLOOKUP(A33,sinap!$A$2:$R$9000,6,FALSE) -> 30-11-2006 | O33: =VLOOKUP(A33,sinap!$A$2:$R$9000,7,FALSE) -> Vivo | P33: =VLOOKUP(A33,sinap!$A$2:$R$9000,8,FALSE) -> 11.1.01.1241 | Q33: =VLOOKUP(A33,sinap!$A$2:$R$9000,12,FALSE) -> 11.2.01.0053 | R33: =VLOOKUP(A33,sinap!$A$2:$R$9000,16,FALSE) -> 11.1.01.0790 | S33: =VLOOKUP(A33,sinap!$A$2:$Y$9000,20,FALSE) -> SI
A34: 1318037 | J34: =VLOOKUP(A34,sinap!$A$2:$R$9000,2,FALSE) -> H | K34: =VLOOKUP(A34,sinap!$A$2:$R$9000,3,FALSE) -> VACA | L34: =VLOOKUP(A34,sinap!$A$2:$R$9000,4,FALSE) -> OVERO COLORADO (CLAVEL ALEMAN) | M34: =VLOOKUP(A34,sinap!$A$2:$R$9000,5,FALSE) -> 19 años 3 meses | N34: =VLOOKUP(A34,sinap!$A$2:$R$9000,6,FALSE) -> 15-10-2006 | O34: =VLOOKUP(A34,sinap!$A$2:$R$9000,7,FALSE) -> Vivo | P34: =VLOOKUP(A34,sinap!$A$2:$R$9000,8,FALSE) -> 11.1.01.1241 | Q34: =VLOOKUP(A34,sinap!$A$2:$R$9000,12,FALSE) -> 11.2.01.0053 | R34: =VLOOKUP(A34,sinap!$A$2:$R$9000,16,FALSE) -> 11.1.01.1241 | S34: =VLOOKUP(A34,sinap!$A$2:$Y$9000,20,FALSE) -> SI
A35: 1318058 | J35: =VLOOKUP(A35,sinap!$A$2:$R$9000,2,FALSE) -> H | K35: =VLOOKUP(A35,sinap!$A$2:$R$9000,3,FALSE) -> VACA | L35: =VLOOKUP(A35,sinap!$A$2:$R$9000,4,FALSE) -> OVERO COLORADO (CLAVEL ALEMAN) | M35: =VLOOKUP(A35,sinap!$A$2:$R$9000,5,FALSE) -> 19 años 3 meses | N35: =VLOOKUP(A35,sinap!$A$2:$R$9000,6,FALSE) -> 15-10-2006 | O35: =VLOOKUP(A35,sinap!$A$2:$R$9000,7,FALSE) -> Vivo | P35: =VLOOKUP(A35,sinap!$A$2:$R$9000,8,FALSE) -> 11.1.01.1241 | Q35: =VLOOKUP(A35,sinap!$A$2:$R$9000,12,FALSE) -> 11.1.01.0893 | R35: =VLOOKUP(A35,sinap!$A$2:$R$9000,16,FALSE) -> 11.1.01.1241 | S35: =VLOOKUP(A35,sinap!$A$2:$Y$9000,20,FALSE) -> SI
A36: 1318076 | J36: =VLOOKUP(A36,sinap!$A$2:$R$9000,2,FALSE) -> H | K36: =VLOOKUP(A36,sinap!$A$2:$R$9000,3,FALSE) -> VACA | L36: =VLOOKUP(A36,sinap!$A$2:$R$9000,4,FALSE) -> ANGUS ROJO | M36: =VLOOKUP(A36,sinap!$A$2:$R$9000,5,FALSE) -> 19 años 4 meses | N36: =VLOOKUP(A36,sinap!$A$2:$R$9000,6,FALSE) -> 15-09-2006 | O36: =VLOOKUP(A36,sinap!$A$2:$R$9000,7,FALSE) -> Vivo | P36: =VLOOKUP(A36,sinap!$A$2:$R$9000,8,FALSE) -> 11.1.01.1241 | Q36: =VLOOKUP(A36,sinap!$A$2:$R$9000,12,FALSE) -> Sin Movimiento | R36: =VLOOKUP(A36,sinap!$A$2:$R$9000,16,FALSE) -> 11.1.01.1241 | S36: =VLOOKUP(A36,sinap!$A$2:$Y$9000,20,FALSE) -> SI
A37: 1318087 | J37: =VLOOKUP(A37,sinap!$A$2:$R$9000,2,FALSE) -> H | K37: =VLOOKUP(A37,sinap!$A$2:$R$9000,3,FALSE) -> VACA | L37: =VLOOKUP(A37,sinap!$A$2:$R$9000,4,FALSE) -> HEREFORD | M37: =VLOOKUP(A37,sinap!$A$2:$R$9000,5,FALSE) -> 19 años 3 meses | N37: =VLOOKUP(A37,sinap!$A$2:$R$9000,6,FALSE) -> 15-10-2006 | O37: =VLOOKUP(A37,sinap!$A$2:$R$9000,7,FALSE) -> Vivo | P37: =VLOOKUP(A37,sinap!$A$2:$R$9000,8,FALSE) -> 11.1.01.1241 | Q37: =VLOOKUP(A37,sinap!$A$2:$R$9000,12,FALSE) -> 11.2.01.0053 | R37: =VLOOKUP(A37,sinap!$A$2:$R$9000,16,FALSE) -> 11.1.01.1241 | S37: =VLOOKUP(A37,sinap!$A$2:$Y$9000,20,FALSE) -> SI
A38: 1318097 | D38: 43983 | E38: 44497 | F38: 44868 | G38: 45253 | J38: =VLOOKUP(A38,sinap!$A$2:$R$9000,2,FALSE) -> H | K38: =VLOOKUP(A38,sinap!$A$2:$R$9000,3,FALSE) -> VACA | L38: =VLOOKUP(A38,sinap!$A$2:$R$9000,4,FALSE) -> HEREFORD | M38: =VLOOKUP(A38,sinap!$A$2:$R$9000,5,FALSE) -> 19 años 2 meses | N38: =VLOOKUP(A38,sinap!$A$2:$R$9000,6,FALSE) -> 15-11-2006 | O38: =VLOOKUP(A38,sinap!$A$2:$R$9000,7,FALSE) -> Vivo | P38: =VLOOKUP(A38,sinap!$A$2:$R$9000,8,FALSE) -> 11.1.01.1241 | Q38: =VLOOKUP(A38,sinap!$A$2:$R$9000,12,FALSE) -> 11.2.01.0053 | R38: =VLOOKUP(A38,sinap!$A$2:$R$9000,16,FALSE) -> 11.1.01.1241 | S38: =VLOOKUP(A38,sinap!$A$2:$Y$9000,20,FALSE) -> SI
A39: 1318106 | D39: 44144 | E39: 44350 | F39: 44868 | G39: 45092 | J39: =VLOOKUP(A39,sinap!$A$2:$R$9000,2,FALSE) -> H | K39: =VLOOKUP(A39,sinap!$A$2:$R$9000,3,FALSE) -> VACA | L39: =VLOOKUP(A39,sinap!$A$2:$R$9000,4,FALSE) -> ANGUS ROJO | M39: =VLOOKUP(A39,sinap!$A$2:$R$9000,5,FALSE) -> 19 años 2 meses | N39: =VLOOKUP(A39,sinap!$A$2:$R$9000,6,FALSE) -> 15-11-2006 | O39: =VLOOKUP(A39,sinap!$A$2:$R$9000,7,FALSE) -> Vivo | P39: =VLOOKUP(A39,sinap!$A$2:$R$9000,8,FALSE) -> 11.1.01.1241 | Q39: =VLOOKUP(A39,sinap!$A$2:$R$9000,12,FALSE) -> Sin Movimiento | R39: =VLOOKUP(A39,sinap!$A$2:$R$9000,16,FALSE) -> 11.1.01.1241 | S39: =VLOOKUP(A39,sinap!$A$2:$Y$9000,20,FALSE) -> SI
A40: 1318116 | D40: 44133 | E40: 44504 | F40: 44857 | G40: 45254 | J40: =VLOOKUP(A40,sinap!$A$2:$R$9000,2,FALSE) -> H | K40: =VLOOKUP(A40,sinap!$A$2:$R$9000,3,FALSE) -> VACA | L40: =VLOOKUP(A40,sinap!$A$2:$R$9000,4,FALSE) -> HEREFORD | M40: =VLOOKUP(A40,sinap!$A$2:$R$9000,5,FALSE) -> 19 años 2 meses | N40: =VLOOKUP(A40,sinap!$A$2:$R$9000,6,FALSE) -> 15-11-2006 | O40: =VLOOKUP(A40,sinap!$A$2:$R$9000,7,FALSE) -> Vivo | P40: =VLOOKUP(A40,sinap!$A$2:$R$9000,8,FALSE) -> 11.1.01.1241 | Q40: =VLOOKUP(A40,sinap!$A$2:$R$9000,12,FALSE) -> 11.2.01.0053 | R40: =VLOOKUP(A40,sinap!$A$2:$R$9000,16,FALSE) -> 11.1.01.1241 | S40: =VLOOKUP(A40,sinap!$A$2:$Y$9000,20,FALSE) -> SI
...

Sheet predios sipec al 16-01-26
A1: NUMERO_DIIO | B1: RAZA | C1: CATEGORIA | D1: FECHA_NACIMIENTO | E1: ESTABLECIMIENTO_NACIDO | F1: SEXO | G1: GLOSA_PABCO | H1: rup
A2: 26234485 | B2: ANGUS NEGRO | C2: TERNERA | D2: 21-12-2025 | E2: ANITA | F2: HEMBRA | G2: NO PABCO | H2: 11.1.01.0791
A3: 26234454 | B3: ANGUS NEGRO | C3: TERNERO | D3: 05-10-2025 | E3: ANITA | F3: MACHO | G3: NO PABCO | H3: 11.1.01.0791
A4: 26234445 | B4: ANGUS NEGRO | C4: TERNERO | D4: 11-09-2025 | E4: ANITA | F4: MACHO | G4: NO PABCO | H4: 11.1.01.0791
A5: 26234436 | B5: ANGUS ROJO | C5: TERNERO | D5: 11-09-2025 | E5: ANITA | F5: MACHO | G5: NO PABCO | H5: 11.1.01.0791
A6: 26234434 | B6: ANGUS NEGRO | C6: TERNERO | D6: 11-09-2025 | E6: ANITA | F6: MACHO | G6: NO PABCO | H6: 11.1.01.0791
A7: 26234430 | B7: ANGUS NEGRO | C7: TERNERO | D7: 11-09-2025 | E7: ANITA | F7: MACHO | G7: NO PABCO | H7: 11.1.01.0791
A8: 26234429 | B8: ANGUS NEGRO | C8: TERNERO | D8: 11-09-2025 | E8: ANITA | F8: MACHO | G8: NO PABCO | H8: 11.1.01.0791
A9: 26234427 | B9: ANGUS NEGRO | C9: TERNERO | D9: 11-09-2025 | E9: ANITA | F9: MACHO | G9: NO PABCO | H9: 11.1.01.0791
A10: 26234425 | B10: ANGUS NEGRO | C10: TERNERA | D10: 11-09-2025 | E10: ANITA | F10: HEMBRA | G10: NO PABCO | H10: 11.1.01.0791
A11: 26234423 | B11: ANGUS NEGRO | C11: TERNERO | D11: 11-09-2025 | E11: ANITA | F11: MACHO | G11: NO PABCO | H11: 11.1.01.0791
A12: 26234421 | B12: ANGUS NEGRO | C12: TERNERO | D12: 11-09-2025 | E12: ANITA | F12: MACHO | G12: NO PABCO | H12: 11.1.01.0791
A13: 26234420 | B13: ANGUS NEGRO | C13: TERNERO | D13: 11-09-2025 | E13: ANITA | F13: MACHO | G13: NO PABCO | H13: 11.1.01.0791
... A1728: 1381820 | B1728: OVERO COLORADO (CLAVEL ALEMAN) | C1728: VACA | D1728: 30-03-2008 | E1728: AGUAS FRESCAS | F1728: HEMBRA | G1728: NO PABCO | H1728: 11.2.01.0038

Sheet iden_sipec
A1: DIIO | B1: sexo | C1: raza | D1: fecha nac. | E1: fecha fiio | F1: rup
A2: 18943034 | B2: HEMBRA | C2: HEREFORD | D2: 44127 | E2: 44141 | F2: 11.1.01.0893
A3: 19050242 | B3: HEMBRA | C3: ANGUS NEGRO | D3: 42292 | E3: 44156 | F3: 11.1.01.0893
A4: 19050244 | B4: HEMBRA | C4: ANGUS NEGRO | D4: 42292 | E4: 44156 | F4: 11.1.01.0893
A5: 19050373 | B5: MACHO | C5: ANGUS NEGRO | D5: 44165 | E5: 44233 | F5: 11.1.01.0893
A6: 19050374 | B6: HEMBRA | C6: ANGUS ROJO | D6: 44165 | E6: 44233 | F6: 11.1.01.0893
A7: 19050375 | B7: HEMBRA | C7: HEREFORD | D7: 44165 | E7: 44233 | F7: 11.1.01.0893
A8: 19050376 | B8: MACHO | C8: ANGUS NEGRO | D8: 44165 | E8: 44233 | F8: 11.1.01.0893
A9: 19050377 | B9: MACHO | C9: ANGUS NEGRO | D9: 44175 | E9: 44233 | F9: 11.1.01.0893
A10: 19050378 | B10: MACHO | C10: ANGUS ROJO | D10: 44165 | E10: 44233 | F10: 11.1.01.0893
A11: 19050379 | B11: MACHO | C11: ANGUS NEGRO | D11: 44155 | E11: 44233 | F11: 11.1.01.0893
A12: 19050380 | B12: HEMBRA | C12: ANGUS ROJO | D12: 44155 | E12: 44233 | F12: 11.1.01.0893
A13: 19050381 | B13: HEMBRA | C13: ANGUS ROJO | D13: 44176 | E13: 44233 | F13: 11.1.01.0893
... A2326: 26234485 | B2326: HEMBRA | C2326: ANGUS NEGRO | D2326: 46012 | E2326: 46012 | F2326: 11.1.01.0893

Sheet chip_toros
A1: DIIO | B1: diio antiguo | C1: chip
A2: 3583874 | C2: 2636134
A3: 9005308 | C3: 2636135
A4: 13447209 | C4: 2636103
A5: 14718282 | C5: 2636125
A6: 14718285 | C6: 2636141
A7: 14718286 | C7: 2636113
A8: 14718287 | C8: 2636102
A9: 14718288 | C9: 2636101
A10: 15417634 | C10: 2636124
A11: 15417643 | C11: 2366120
A12: 16190664 | C12: 2636122
A13: 16190671 | C13: 2636117
... A30: 16843140 | C30: 2636114
A31: 18071569 | B31: 13349320 | C31: 2636109
A32: 18072806 | C32: 2636151
A33: 18072830 | C33: 2636147
A34: 19050220 | C34: 2636116
A35: 19050221 | C35: 2636111
A36: 19050222 | C36: 2636107
A37: 19050223 | C37: 2636103
A38: 19050224 | C38: 2636105
A39: 19050225 | C39: 2636106
A40: 19050226 | C40: 2636131
A41: 19050228 | C41: 2636123
A42: 19050229 | C42: 2636122
A43: 19050230 | C43: 2636133
... A66: 20910768 | C66: 2636160
A67: 20910769 | B67: 19776849 | C67: 2636170
A68: 21070641 | C68: 2636178
A69: 26126981 | B69: 22350410 | C69: 2636162
A70: 23323649 | C70: 2636171
A71: 23323650 | B71: 15417634 | C71: 2636124

Sheet cambio_diio
A1: DIIO NUEVO | B1: DIIO ANTIGUO | C1: FECHA CAMBIO | D1: rup
A2: 20910612 | B2: 6154958 | C2: 44727 | D2: 11.1.01.1241
A3: 20910613 | B3: 6154794 | C3: 44727 | D3: 11.1.01.1241
A4: 20910614 | B4: 8392827 | C4: 44727 | D4: 11.1.01.1241
A5: 20910615 | B5: 15661075 | C5: 44727 | D5: 11.1.01.1241
A6: 16390476 | B6: 16705762 | C6: 44745 | D6: 11.1.01.1241
A7: 16390576 | B7: 8092341 | C7: 44858 | D7: 11.1.01.1241
A8: 16390577 | B8: 8935764 | C8: 44858 | D8: 11.1.01.1241
A9: 16390578 | B9: 8392642 | C9: 44868 | D9: 11.1.01.1241
A10: 16390579 | B10: 8933216 | C10: 44868 | D10: 11.1.01.1241
A11: 16390580 | B11: 14717842 | C11: 44868 | D11: 11.1.01.1241
A12: 16390581 | B12: 8937709 | C12: 44868 | D12: 11.1.01.1241
A13: 16390583 | B13: 14718063 | C13: 44880 | D13: 11.1.01.1022
... A43: 20910740 | B43: 8937516 | C43: 45240 | D43: 11.1.01.1241
A44: reversado | B44: 20910269 | C44: 45240 | D44: 11.1.01.1241 | E44: reversado cambio 20910741
A45: 20910744 | B45: 9320741 | C45: 45253 | D45: 11.1.01.0893
A46: 20910745 | B46: 16843324 | C46: 45253 | D46: 11.1.01.0893
A47: 20910746 | B47: 16843316 | C47: 45253 | D47: 11.1.01.0893
A48: 20910747 | B48: 8937616 | C48: 45253 | D48: 11.1.01.0893
A49: 20910748 | B49: 14717789 | C49: 45253 | D49: 11.1.01.0893
A50: 20910749 | B50: 14717844 | C50: 45261 | D50: 11.1.01.1241
A51: 20910753 | B51: 16843227 | C51: 45265 | D51: 11.1.01.0893
A52: 20910755 | B52: 16843155 | C52: 45265 | D52: 11.1.01.0893
A53: 20910757 | B53: 16843343 | C53: 45265 | D53: 11.1.01.0893
A54: 20910759 | B54: 16843022 | C54: 45265 | D54: 11.1.01.0893
A55: 20910760 | B55: 16843218 | C55: 45265 | D55: 11.1.01.0893
A56: 22350426 | B56: 22350243 | C56: 45269 | D56: 11.1.01.1241
... A109: 24567609 | B109: 24567049 | C109: 45890 | D109: 11.2.01.0053
A110: 26126982 | B110: 8933598 | C110: 45958
A111: 26126981 | B111: 22350410 | C111: 45958
A112: 26126983 | B112: 23323333 | C112: 45958
A113: 23323676 | B113: 15661176 | C113: 45965 | D113: 11.1.01.1241
A114: 23323676 | B114: 15661176 | C114: 45966 | D114: 11.1.01.1241
A115: 23323679 | B115: 18943053 | C115: 45966 | D115: 11.1.01.1241
A116: 23323680 | B116: 23323655 | C116: 45966 | D116: 11.1.01.1241
A117: 23323670 | B117: 24567522 | C117: 45966 | D117: 11.1.01.1241
A118: 23323681 | B118: 24567508 | C118: 45966 | D118: 11.1.01.1241
A119: 23323678 | B119: 24567520 | C119: 45966 | D119: 11.1.01.1241
A120: 23323678 | B120: 24567520 | C120: 45966 | D120: 11.1.01.1241
A121: 23323681 | B121: 24567508 | C121: 45966 | D121: 11.1.01.1241
...

Sheet sinap
A1: DIIO | B1: Sexo | C1: Clase | D1: Raza | E1: Edad | F1: Fecha_Nacimiento | G1: Estado | H1: Rup_Actual | I1: Nombre_Titular_Ubicacion_Actual | J1: Nombre_Predio_Ubicacion_Actual | K1: Cantidad_Titulares | L1: RUP_ultimo_movimiento | M1: Uso_Anabolicos | N1: Trazabilidad_Nacimiento | O1: Trazabilidad_Completa | P1: Rup_Origen | Q1: PABCO | R1: Uso_Medicamento_No_Permitido | S1: Estado_RUP_Actual | T1: Exportable_CHINA | U1: Exportable_UE
A2: 55956 | B2: M | C2: BUEY | D2: OVERO COLORADO (CLAVEL ALEMAN) | E2: 23 años 11 meses | F2: 08-02-2002 | G2: Vivo | H2: 11.1.01.1241 | I2: MARIA ERCIRA | J2: STA MARIA 2 | K2: 4 | L2: 11.1.01.0789 | M2: NO | N2: SI | O2: SI | P2: 11.1.01.0790 | Q2: NO | R2: No | S2: BLOQUEADO | T2: SI | U2: NO
A3: 83926 | B3: M | C3: BUEY | D3: ANGUS NEGRO | E3: 21 años 4 meses | F3: 15-09-2004 | G3: Vivo | H3: 11.1.01.1241 | I3: MARIA ERCIRA | J3: STA MARIA 2 | K3: 4 | L3: 11.1.01.0291 | M3: NO | N3: SI | O3: SI | P3: 11.1.01.0290 | Q3: NO | R3: No | S3: BLOQUEADO | T3: SI | U3: NO
A4: 84361 | B4: H | C4: VACA | D4: POLLED HEREFORD | E4: 22 años 3 meses | F4: 15-10-2003 | G4: Vivo | H4: 11.1.01.1241 | I4: MARIA ERCIRA | J4: STA MARIA 2 | K4: 4 | L4: 11.1.01.0791 | M4: NO | N4: SI | O4: SI | P4: 11.1.01.1241 | Q4: NO | R4: No | S4: BLOQUEADO | T4: SI | U4: NO
A5: 84362 | B5: H | C5: VACA | D5: POLLED HEREFORD | E5: 22 años 3 meses | F5: 15-10-2003 | G5: Vivo | H5: 11.1.01.1241 | I5: MARIA ERCIRA | J5: STA MARIA 2 | K5: 4 | L5: Sin Movimiento | M5: NO | N5: SI | O5: SI | P5: 11.1.01.1241 | Q5: NO | R5: No | S5: BLOQUEADO | T5: SI | U5: NO
A6: 84369 | B6: H | C6: VACA | D6: OVERO COLORADO (CLAVEL ALEMAN) | E6: 22 años 3 meses | F6: 15-10-2003 | G6: Vivo | H6: 11.1.01.1241 | I6: MARIA ERCIRA | J6: STA MARIA 2 | K6: 4 | L6: Sin Movimiento | M6: NO | N6: SI | O6: SI | P6: 11.1.01.1241 | Q6: NO | R6: No | S6: BLOQUEADO | T6: SI | U6: NO
A7: 84393 | B7: H | C7: VACA | D7: POLLED HEREFORD | E7: 22 años 3 meses | F7: 15-10-2003 | G7: Vivo | H7: 11.1.01.1241 | I7: MARIA ERCIRA | J7: STA MARIA 2 | K7: 4 | L7: 11.1.01.1081 | M7: NO | N7: SI | O7: SI | P7: 11.1.01.1241 | Q7: NO | R7: No | S7: BLOQUEADO | T7: SI | U7: NO
A8: 84403 | B8: H | C8: VACA | D8: POLLED HEREFORD | E8: 22 años 3 meses | F8: 15-10-2003 | G8: Vivo | H8: 11.1.01.1241 | I8: MARIA ERCIRA | J8: STA MARIA 2 | K8: 4 | L8: Sin Movimiento | M8: NO | N8: SI | O8: SI | P8: 11.1.01.1241 | Q8: NO | R8: No | S8: BLOQUEADO | T8: SI | U8: NO
A9: 84427 | B9: H | C9: VACA | D9: ANGUS ROJO | E9: 21 años 3 meses | F9: 15-10-2004 | G9: Vivo | H9: 11.1.01.1241 | I9: MARIA ERCIRA | J9: STA MARIA 2 | K9: 4 | L9: 11.1.01.0790 | M9: NO | N9: SI | O9: SI | P9: 11.1.01.0789 | Q9: NO | R9: No | S9: BLOQUEADO | T9: SI | U9: NO
A10: 84463 | B10: H | C10: VACA | D10: OVERO COLORADO (CLAVEL ALEMAN) | E10: 22 años 3 meses | F10: 15-10-2003 | G10: Vivo | H10: 11.1.01.1241 | I10: MARIA ERCIRA | J10: STA MARIA 2 | K10: 4 | L10: Sin Movimiento | M10: NO | N10: SI | O10: SI | P10: 11.1.01.1241 | Q10: NO | R10: No | S10: BLOQUEADO | T10: SI | U10: NO
A11: 84657 | B11: H | C11: VACA | D11: HEREFORD | E11: 23 años 3 meses | F11: 15-10-2002 | G11: Vivo | H11: 11.1.01.1241 | I11: MARIA ERCIRA | J11: STA MARIA 2 | K11: 4 | L11: 11.1.01.0791 | M11: NO | N11: SI | O11: SI | P11: 11.1.01.0791 | Q11: NO | R11: No | S11: BLOQUEADO | T11: SI | U11: NO
A12: 93136 | B12: M | C12: BUEY | D12: ANGUS NEGRO | E12: 20 años 3 meses | F12: 25-09-2005 | G12: Vivo | H12: 11.1.01.1241 | I12: MARIA ERCIRA | J12: STA MARIA 2 | K12: 4 | L12: 11.1.01.0790 | M12: NO | N12: SI | O12: NO | P12: 11.1.01.0831 | Q12: NO | R12: No | S12: BLOQUEADO | T12: SI | U12: NO
A13: 133342 | B13: M | C13: BUEY | D13: OVERO COLORADO (CLAVEL ALEMAN) | E13: 20 años 3 meses | F13: 15-10-2005 | G13: Vivo | H13: 11.1.01.1241 | I13: MARIA ERCIRA | J13: STA MARIA 2 | K13: 4 | L13: 11.1.01.0893 | M13: NO | N13: SI | O13: NO | P13: 11.1.01.0932 | Q13: NO | R13: No | S13: BLOQUEADO | T13: SI | U13: NO
... A2970: 24567395 | B2970: M | C2970: TERNERO | D2970: ANGUS NEGRO | E2970: 1 años 8 meses | F2970: 30-04-2024 | G2970: Muerto | H2970: 11.1.01.2002 | I2970: SOCIEDAD COMERCIAL INDUCAR LTDA. | J2970: MATADERO INDUCAR DE COYHAIQUE | K2970: 2 | L2970: 11.1.01.0190 | M2970: NO | N2970: SI | O2970: SI | P2970: 11.1.01.1241 | Q2970: NO | R2970: No | S2970: NO BLOQUEADO | T2970: SI | U2970: NO
A2971: 20910602 | B2971: no existe | C2971: no existe | D2971: no existe | E2971: no existe | F2971: no existe | G2971: no existe | H2971: no existe | I2971: no existe | J2971: no existe | K2971: no existe | L2971: no existe | M2971: no existe | N2971: no existe | O2971: no existe | P2971: no existe | Q2971: no existe | R2971: no existe | S2971: no existe | T2971: no existe | U2971: no existe | V2971: no existe
A2972: 22350001 | B2972: no existe | C2972: no existe | D2972: no existe | E2972: no existe | F2972: no existe | G2972: no existe | H2972: no existe | I2972: no existe | J2972: no existe | K2972: no existe | L2972: no existe | M2972: no existe | N2972: no existe | O2972: no existe | P2972: no existe | Q2972: no existe | R2972: no existe | S2972: no existe | T2972: no existe | U2972: no existe | V2972: no existe
A2973: 22350050 | B2973: no existe | C2973: no existe | D2973: no existe | E2973: no existe | F2973: no existe | G2973: no existe | H2973: no existe | I2973: no existe | J2973: no existe | K2973: no existe | L2973: no existe | M2973: no existe | N2973: no existe | O2973: no existe | P2973: no existe | Q2973: no existe | R2973: no existe | S2973: no existe | T2973: no existe | U2973: no existe | V2973: no existe
A2974: 22350046 | B2974: no existe | C2974: no existe | D2974: no existe | E2974: no existe | F2974: no existe | G2974: no existe | H2974: no existe | I2974: no existe | J2974: no existe | K2974: no existe | L2974: no existe | M2974: no existe | N2974: no existe | O2974: no existe | P2974: no existe | Q2974: no existe | R2974: no existe | S2974: no existe | T2974: no existe | U2974: no existe | V2974: no existe
A2975: 22350134 | B2975: no existe | C2975: no existe | D2975: no existe | E2975: no existe | F2975: no existe | G2975: no existe | H2975: no existe | I2975: no existe | J2975: no existe | K2975: no existe | L2975: no existe | M2975: no existe | N2975: no existe | O2975: no existe | P2975: no existe | Q2975: no existe | R2975: no existe | S2975: no existe | T2975: no existe | U2975: no existe | V2975: no existe
A2976: 22350201 | B2976: no existe | C2976: no existe | D2976: no existe | E2976: no existe | F2976: no existe | G2976: no existe | H2976: no existe | I2976: no existe | J2976: no existe | K2976: no existe | L2976: no existe | M2976: no existe | N2976: no existe | O2976: no existe | P2976: no existe | Q2976: no existe | R2976: no existe | S2976: no existe | T2976: no existe | U2976: no existe | V2976: no existe
A2977: 22350243 | B2977: no existe | C2977: no existe | D2977: no existe | E2977: no existe | F2977: no existe | G2977: no existe | H2977: no existe | I2977: no existe | J2977: no existe | K2977: no existe | L2977: no existe | M2977: no existe | N2977: no existe | O2977: no existe | P2977: no existe | Q2977: no existe | R2977: no existe | S2977: no existe | T2977: no existe | U2977: no existe | V2977: no existe
A2978: 22350263 | B2978: no existe | C2978: no existe | D2978: no existe | E2978: no existe | F2978: no existe | G2978: no existe | H2978: no existe | I2978: no existe | J2978: no existe | K2978: no existe | L2978: no existe | M2978: no existe | N2978: no existe | O2978: no existe | P2978: no existe | Q2978: no existe | R2978: no existe | S2978: no existe | T2978: no existe | U2978: no existe | V2978: no existe
A2979: 22350379 | B2979: no existe | C2979: no existe | D2979: no existe | E2979: no existe | F2979: no existe | G2979: no existe | H2979: no existe | I2979: no existe | J2979: no existe | K2979: no existe | L2979: no existe | M2979: no existe | N2979: no existe | O2979: no existe | P2979: no existe | Q2979: no existe | R2979: no existe | S2979: no existe | T2979: no existe | U2979: no existe | V2979: no existe
A2980: 22350410 | B2980: no existe | C2980: no existe | D2980: no existe | E2980: no existe | F2980: no existe | G2980: no existe | H2980: no existe | I2980: no existe | J2980: no existe | K2980: no existe | L2980: no existe | M2980: no existe | N2980: no existe | O2980: no existe | P2980: no existe | Q2980: no existe | R2980: no existe | S2980: no existe | T2980: no existe | U2980: no existe | V2980: no existe
A2981: 20910649 | B2981: no existe | C2981: no existe | D2981: no existe | E2981: no existe | F2981: no existe | G2981: no existe | H2981: no existe | I2981: no existe | J2981: no existe | K2981: no existe | L2981: no existe | M2981: no existe | N2981: no existe | O2981: no existe | P2981: no existe | Q2981: no existe | R2981: no existe | S2981: no existe | T2981: no existe | U2981: no existe | V2981: no existe
A2982: 23323333 | B2982: no existe | C2982: no existe | D2982: no existe | E2982: no existe | F2982: no existe | G2982: no existe | H2982: no existe | I2982: no existe | J2982: no existe | K2982: no existe | L2982: no existe | M2982: no existe | N2982: no existe | O2982: no existe | P2982: no existe | Q2982: no existe | R2982: no existe | S2982: no existe | T2982: no existe | U2982: no existe | V2982: no existe
... A2992: 24567205 | B2992: no existe | C2992: no existe | D2992: no existe | E2992: no existe | F2992: no existe | G2992: no existe | H2992: no existe | I2992: no existe | J2992: no existe | K2992: no existe | L2992: no existe | M2992: no existe | N2992: no existe | O2992: no existe | P2992: no existe | Q2992: no existe | R2992: no existe | S2992: no existe | T2992: no existe | U2992: no existe | V2992: no existe
A2993: 24567396 | B2993: M | C2993: NOVILLO | D2993: ANGUS NEGRO | E2993: 1 años 8 meses | F2993: 30-04-2024 | G2993: Vivo | H2993: 11.1.01.0964 | I2993: SUR INVERSIONES LTDA INGASUR | J2993: LOS TRINOS | K2993: 8 | L2993: 11.1.01.0190 | M2993: NO | N2993: SI | O2993: SI | P2993: 11.1.01.1241 | Q2993: NO | R2993: No | S2993: NO BLOQUEADO | T2993: SI | U2993: NO
A2994: 24567397 | B2994: M | C2994: TERNERO | D2994: ANGUS NEGRO | E2994: 1 años 8 meses | F2994: 30-04-2024 | G2994: Muerto | H2994: 11.1.01.2002 | I2994: SOCIEDAD COMERCIAL INDUCAR LTDA. | J2994: MATADERO INDUCAR DE COYHAIQUE | K2994: 2 | L2994: 11.1.01.0190 | M2994: NO | N2994: SI | O2994: SI | P2994: 11.1.01.1241 | Q2994: NO | R2994: No | S2994: NO BLOQUEADO | T2994: SI | U2994: NO
A2995: 24567398 | B2995: M | C2995: NOVILLO | D2995: ANGUS ROJO | E2995: 1 años 8 meses | F2995: 30-04-2024 | G2995: Vivo | H2995: 11.1.01.0964 | I2995: SUR INVERSIONES LTDA INGASUR | J2995: LOS TRINOS | K2995: 8 | L2995: 11.1.01.0190 | M2995: NO | N2995: SI | O2995: SI | P2995: 11.1.01.1241 | Q2995: NO | R2995: No | S2995: NO BLOQUEADO | T2995: SI | U2995: NO
A2996: 23323605 | B2996: M | C2996: NOVILLO | D2996: ANGUS NEGRO | E2996: 1 años 11 meses | F2996: 30-01-2024 | G2996: Vivo | H2996: 07.1.06.0174 | I2996: RIVERA MALDONADO MARIA PAZ | J2996: FUNDO EL LLANO | K2996: 9 | L2996: 07.1.06.0586 | M2996: SI | N2996: SI | O2996: SI | P2996: 11.1.01.1241 | Q2996: NO | R2996: No | S2996: NO BLOQUEADO | T2996: NO | U2996: NO
A2997: 23323608 | B2997: M | C2997: NOVILLO | D2997: ANGUS NEGRO | E2997: 1 años 11 meses | F2997: 30-01-2024 | G2997: Vivo | H2997: 14.2.03.0728 | I2997: AGRICOLA KAIKEN LIMITADA | J2997: FUNDO CHUCAO (CUENTA Y CLAVE SIPECWEB) | K2997: 4 | L2997: 10.1.09.0165 | M2997: NO | N2997: SI | O2997: SI | P2997: 11.1.01.1241 | Q2997: NO | R2997: No | S2997: NO BLOQUEADO | T2997: SI | U2997: NO
A2998: 23323609 | B2998: M | C2998: NOVILLO | D2998: ANGUS NEGRO | E2998: 1 años 9 meses | F2998: 30-03-2024 | G2998: Vivo | H2998: 10.3.02.0765 | I2998: PUCHI ACUÑA MARIO HUMBERTO | J2998: FUNDO PUERTO FONCK | K2998: 12 | L2998: 11.1.01.2512 | M2998: NO | N2998: SI | O2998: SI | P2998: 11.1.01.1241 | Q2998: SI | R2998: No | S2998: BLOQUEADO | T2998: SI | U2998: SI
A2999: 23323610 | B2999: M | C2999: NOVILLO | D2999: ANGUS ROJO | E2999: 1 años 11 meses | F2999: 30-01-2024 | G2999: Vivo | H2999: 07.1.06.0150 | I2999: GUSTAVO ADOLFO | J2999: FUNDO EL MANZANO | K2999: 8 | L2999: 07.3.01.0148 | M2999: SI | N2999: SI | O2999: SI | P2999: 11.1.01.1241 | Q2999: NO | R2999: No | S2999: BLOQUEADO | T2999: NO | U2999: NO
A3000: 23323613 | B3000: H | C3000: VAQUILLA | D3000: ANGUS NEGRO | E3000: 1 años 10 meses | F3000: 28-02-2024 | G3000: Muerto | H3000: 11.1.01.0893 | I3000: MARIA ERCIRA | J3000: ANITA | K3000: 7 | L3000: 11.1.01.1241 | M3000: NO | N3000: SI | O3000: SI | P3000: 11.1.01.1241 | Q3000: NO | R3000: No | S3000: BLOQUEADO | T3000: SI | U3000: NO
A3001: 23323615 | B3001: M | C3001: NOVILLO | D3001: ANGUS NEGRO | E3001: 1 años 11 meses | F3001: 30-01-2024 | G3001: Vivo | H3001: 14.2.03.0728 | I3001: AGRICOLA KAIKEN LIMITADA | J3001: FUNDO CHUCAO (CUENTA Y CLAVE SIPECWEB) | K3001: 4 | L3001: 10.1.09.0165 | M3001: NO | N3001: SI | O3001: SI | P3001: 11.1.01.1241 | Q3001: NO | R3001: No | S3001: NO BLOQUEADO | T3001: SI | U3001: NO
A3002: 23323616 | B3002: M | C3002: NOVILLO | D3002: ANGUS ROJO | E3002: 1 años 11 meses | F3002: 30-01-2024 | G3002: Vivo | H3002: 11.1.01.0964 | I3002: SUR INVERSIONES LTDA INGASUR | J3002: LOS TRINOS | K3002: 8 | L3002: 11.1.01.0190 | M3002: NO | N3002: SI | O3002: SI | P3002: 11.1.01.1241 | Q3002: NO | R3002: No | S3002: NO BLOQUEADO | T3002: SI | U3002: NO
A3003: 23323617 | B3003: M | C3003: NOVILLO | D3003: ANGUS NEGRO | E3003: 2 años 1 meses | F3003: 30-11-2023 | G3003: Vivo | H3003: 07.1.06.0150 | I3003: GUSTAVO ADOLFO | J3003: FUNDO EL MANZANO | K3003: 8 | L3003: 07.1.10.0509 | M3003: SI | N3003: SI | O3003: SI | P3003: 11.1.01.1241 | Q3003: NO | R3003: No | S3003: BLOQUEADO | T3003: NO | U3003: NO
A3004: 23323620 | B3004: M | C3004: NOVILLO | D3004: ANGUS NEGRO | E3004: 2 años 0 meses | F3004: 30-12-2023 | G3004: Muerto | H3004: 08.4.01.9001 | I3004: LUÍS MICHEL | J3004: FRIGOSUR LTDA. | K3004: 5 | L3004: 07.1.06.0150 | M3004: SI | N3004: SI | O3004: SI | P3004: 11.1.01.1241 | Q3004: NO | R3004: No | S3004: NO BLOQUEADO | T3004: NO | U3004: NO
... A3642: 23584127 | B3642: M | C3642: NOVILLO | D3642: ANGUS NEGRO | E3642: 2 años 3 meses | F3642: 15-10-2023 | G3642: Vivo | H3642: 11.1.01.1241 | I3642: MARIA ERCIRA | J3642: STA MARIA 2 | K3642: 4 | L3642: 11.1.01.2408 | M3642: NO | N3642: SI | O3642: SI | P3642: 11.1.01.0290 | Q3642: NO | R3642: No | S3642: BLOQUEADO | T3642: SI | U3642: NO

Sheet manejos_25
A1: DIIO | B1: FECHA | C1: RUP
A2: 8092117 | B2: 45966 | C2: 11.1.01.1241 | D2: 70 vacas parias Covexin 10 - 2ml, Virbamec F-10ml y Vit-E-Selenio -10 m
A3: 8092346 | B3: 45671 | C3: 11.1.01.1241
A4: 8202197 | B4: 45965 | C4: 11.1.01.1241 | D4: 32 vacas paridas Clostribac 8 Gold - 2ml, Virbamec F-10ml y Vit-E-Selenio -10 ml
A5: 8202197 | B5: 45671 | C5: 11.1.01.1241
A6: 8392502 | B6: 45671 | C6: 11.1.01.1241
A7: 8392502 | B7: 45671 | C7: 11.1.01.1241 | D7: VC PALPADAS RECHAZO
A8: 8933139 | B8: 45671 | C8: 11.1.01.1241
A9: 8933152 | B9: 45671 | C9: 11.1.01.1241
A10: 8933220 | B10: 45671 | C10: 11.1.01.1241
A11: 8933222 | B11: 45671 | C11: 11.1.01.1241
A12: 8933290 | B12: 45966 | C12: 11.1.01.1241 | D12: 70 vacas parias Covexin 10 - 2ml, Virbamec F-10ml y Vit-E-Selenio -10 m
A13: 8933290 | B13: 45671 | C13: 11.1.01.1241
A14: 8933598 | B14: 45671 | C14: 11.1.01.1241
A15: 8935771 | B15: 45671 | C15: 11.1.01.1241
A16: 8935828 | B16: 45671 | C16: 11.1.01.1241
A17: 8935828 | B17: 45671 | C17: 11.1.01.1241 | D17: VC PALPADAS RECHAZO
A18: 8937607 | B18: 45671 | C18: 11.1.01.1241
A19: 8937646 | B19: 45966 | C19: 11.1.01.1241 | D19: 70 vacas parias Covexin 10 - 2ml, Virbamec F-10ml y Vit-E-Selenio -10 m
A20: 8937646 | B20: 45671 | C20: 11.1.01.1241
A21: 8937718 | B21: 45966 | C21: 11.1.01.1241 | D21: 70 vacas parias Covexin 10 - 2ml, Virbamec F-10ml y Vit-E-Selenio -10 m
A22: 8937718 | B22: 45671 | C22: 11.1.01.1241
A23: 8939132 | B23: 45671 | C23: 11.1.01.1241
A24: 10281938 | B24: 45671 | C24: 11.1.01.1241
A25: 10932065 | B25: 45965 | C25: 11.1.01.1241 | D25: 41 vacas preñadas Clostribac 8 gold
A26: 10932065 | B26: 45813 | C26: 11.2.01.0038 | D26: Clostribac 8 Gold + Cydectin 1%+ Selenio +Vitamina A+Vitamina D3+Vitamina E
A27: 10932065 | B27: 45671 | C27: 11.1.01.1241
A28: 10932160 | B28: 45813 | C28: 11.2.01.0038 | D28: Clostribac 8 Gold + Cydectin 1%+ Selenio +Vitamina A+Vitamina D3+Vitamina E
A29: 10932160 | B29: 45671 | C29: 11.1.01.1241
A30: 10943295 | B30: 45671 | C30: 11.1.01.1241
A31: 12602055 | B31: 45671 | C31: 11.1.01.1241
A32: 12602055 | B32: 45671 | C32: 11.1.01.1241 | D32: VC PALPADAS RECHAZO
A33: 12602064 | B33: 45965 | C33: 11.1.01.1241 | D33: 53 VACAS PARIAS + 6 TOROS, Covexin 10 - 2ml, Virbamec F-10ml y Vit-E-Selenio -10 ml
A34: 12602064 | B34: 45671 | C34: 11.1.01.1241
A35: 12602152 | B35: 45965 | C35: 11.1.01.1241 | D35: 53 VACAS PARIAS + 6 TOROS, Covexin 10 - 2ml, Virbamec F-10ml y Vit-E-Selenio -10 ml
A36: 12602152 | B36: 45671 | C36: 11.1.01.1241
A37: 12602292 | B37: 45671 | C37: 11.1.01.1241
A38: 12602332 | B38: 45671 | C38: 11.1.01.1241
A39: 12602337 | B39: 45848 | C39: 11.1.01.0893 | D39: palpadas
A40: 12602368 | B40: 45671 | C40: 11.1.01.1241
...
